Workbook

Sheet README
A1: 衣装管理システム（Excel）README
A3: ■ 概要
A4: このファイルは、衣装・小物・セット・貸出履歴を一括管理するためのExcel管理です。
A5: 個体単位の衣装管理から、セット構成、貸出状況、履歴確認までを一つのファイルで管理できます。
A7: 衣装が数百点ある場合でも、IDによる管理と自動参照によって整理された状態を保てる構造になっています。
A9: 主な目的
A10: ・衣装の個体管理
A11: ・衣装セットの管理
A12: ・貸出履歴の記録
A13: ・現在貸出中の衣装確認
A14: ・管理ミスのチェック
A17: ■ シート構成
... A105: Project-R広島
A106: 46113
A109: 4. 返却処理
A110: 返却された場合は返却日に日付を入力します。
A113: 5. 貸出状況確認
A114: 現在貸出シートを確認すると、貸出中の衣装が一覧で確認できます。
A117: ■ IDルール（推奨）
A119: 個体ID
A120: ITM-0001
A122: セットID
A123: M-001
A125: 貸出ID
A126: BT-0001
A128: IDは重複しないように管理してください。
... A186: 衣装管理Excel

Sheet エラーチェック
A2: 長期貸出 | B2: {=IFERROR(INDEX(貸出記録!$A:$A, SMALL(IF(貸出記録!$K:$K=1,ROW(貸出記録!$A:$A)),ROW(A1)) ),"")} | C2: =IF(B2="","", "31日以上返却されていない")
B3: {=IFERROR(INDEX(貸出記録!$A:$A, SMALL(IF(貸出記録!$K:$K=1,ROW(貸出記録!$A:$A)),ROW(A2)) ),"")} | C3: =IF(B3="","", "31日以上返却されていない")
B4: {=IFERROR(INDEX(貸出記録!$A:$A, SMALL(IF(貸出記録!$K:$K=1,ROW(貸出記録!$A:$A)),ROW(A3)) ),"")} | C4: =IF(B4="","", "31日以上返却されていない")
B5: {=IFERROR(INDEX(貸出記録!$A:$A, SMALL(IF(貸出記録!$K:$K=1,ROW(貸出記録!$A:$A)),ROW(A4)) ),"")} | C5: =IF(B5="","", "31日以上返却されていない")
B6: {=IFERROR(INDEX(貸出記録!$A:$A, SMALL(IF(貸出記録!$K:$K=1,ROW(貸出記録!$A:$A)),ROW(A5)) ),"")} | C6: =IF(B6="","", "31日以上返却されていない")
B7: {=IFERROR(INDEX(貸出記録!$A:$A, SMALL(IF(貸出記録!$K:$K=1,ROW(貸出記録!$A:$A)),ROW(A6)) ),"")} | C7: =IF(B7="","", "31日以上返却されていない")
B8: {=IFERROR(INDEX(貸出記録!$A:$A, SMALL(IF(貸出記録!$K:$K=1,ROW(貸出記録!$A:$A)),ROW(A7)) ),"")} | C8: =IF(B8="","", "31日以上返却されていない")
B9: {=IFERROR(INDEX(貸出記録!$A:$A, SMALL(IF(貸出記録!$K:$K=1,ROW(貸出記録!$A:$A)),ROW(A8)) ),"")} | C9: =IF(B9="","", "31日以上返却されていない")
B10: {=IFERROR(INDEX(貸出記録!$A:$A, SMALL(IF(貸出記録!$K:$K=1,ROW(貸出記録!$A:$A)),ROW(A9)) ),"")} | C10: =IF(B10="","", "31日以上返却されていない")
B11: {=IFERROR(INDEX(貸出記録!$A:$A, SMALL(IF(貸出記録!$K:$K=1,ROW(貸出記録!$A:$A)),ROW(A10)) ),"")} | C11: =IF(B11="","", "31日以上返却されていない")
B12: {=IFERROR(INDEX(貸出記録!$A:$A, SMALL(IF(貸出記録!$K:$K=1,ROW(貸出記録!$A:$A)),ROW(A11)) ),"")} | C12: =IF(B12="","", "31日以上返却されていない")
B13: {=IFERROR(INDEX(貸出記録!$A:$A, SMALL(IF(貸出記録!$K:$K=1,ROW(貸出記録!$A:$A)),ROW(A12)) ),"")} | C13: =IF(B13="","", "31日以上返却されていない")
B14: {=IFERROR(INDEX(貸出記録!$A:$A, SMALL(IF(貸出記録!$K:$K=1,ROW(貸出記録!$A:$A)),ROW(A13)) ),"")} | C14: =IF(B14="","", "31日以上返却されていない")
... B19: {=IFERROR(INDEX(貸出記録!$A:$A, SMALL(IF(貸出記録!$K:$K=1,ROW(貸出記録!$A:$A)),ROW(A18)) ),"")} | C19: =IF(B19="","", "31日以上返却されていない")
A20: 状態矛盾 | B20: {=IFERROR(INDEX(貸出記録!$B:$B, SMALL(IF(貸出記録!$L:$L=1,ROW(貸出記録!$B:$B)),ROW(A1)) ),"")} | C20: =IF(B20="","", "貸出中なのに個体台帳の状態が一致しない（在庫/洗濯中/廃棄 等）")
B21: {=IFERROR(INDEX(貸出記録!$B:$B, SMALL(IF(貸出記録!$L:$L=1,ROW(貸出記録!$B:$B)),ROW(A2)) ),"")} | C21: =IF(B21="","", "貸出中なのに個体台帳の状態が一致しない（在庫/洗濯中/廃棄 等）")
B22: {=IFERROR(INDEX(貸出記録!$B:$B, SMALL(IF(貸出記録!$L:$L=1,ROW(貸出記録!$B:$B)),ROW(A3)) ),"")} | C22: =IF(B22="","", "貸出中なのに個体台帳の状態が一致しない（在庫/洗濯中/廃棄 等）")
B23: {=IFERROR(INDEX(貸出記録!$B:$B, SMALL(IF(貸出記録!$L:$L=1,ROW(貸出記録!$B:$B)),ROW(A4)) ),"")} | C23: =IF(B23="","", "貸出中なのに個体台帳の状態が一致しない（在庫/洗濯中/廃棄 等）")
B24: {=IFERROR(INDEX(貸出記録!$B:$B, SMALL(IF(貸出記録!$L:$L=1,ROW(貸出記録!$B:$B)),ROW(A5)) ),"")} | C24: =IF(B24="","", "貸出中なのに個体台帳の状態が一致しない（在庫/洗濯中/廃棄 等）")
B25: {=IFERROR(INDEX(貸出記録!$B:$B, SMALL(IF(貸出記録!$L:$L=1,ROW(貸出記録!$B:$B)),ROW(A6)) ),"")} | C25: =IF(B25="","", "貸出中なのに個体台帳の状態が一致しない（在庫/洗濯中/廃棄 等）")
B26: {=IFERROR(INDEX(貸出記録!$B:$B, SMALL(IF(貸出記録!$L:$L=1,ROW(貸出記録!$B:$B)),ROW(A7)) ),"")} | C26: =IF(B26="","", "貸出中なのに個体台帳の状態が一致しない（在庫/洗濯中/廃棄 等）")
B27: {=IFERROR(INDEX(貸出記録!$B:$B, SMALL(IF(貸出記録!$L:$L=1,ROW(貸出記録!$B:$B)),ROW(A8)) ),"")} | C27: =IF(B27="","", "貸出中なのに個体台帳の状態が一致しない（在庫/洗濯中/廃棄 等）")
B28: {=IFERROR(INDEX(貸出記録!$B:$B, SMALL(IF(貸出記録!$L:$L=1,ROW(貸出記録!$B:$B)),ROW(A9)) ),"")} | C28: =IF(B28="","", "貸出中なのに個体台帳の状態が一致しない（在庫/洗濯中/廃棄 等）")
B29: {=IFERROR(INDEX(貸出記録!$B:$B, SMALL(IF(貸出記録!$L:$L=1,ROW(貸出記録!$B:$B)),ROW(A10)) ),"")} | C29: =IF(B29="","", "貸出中なのに個体台帳の状態が一致しない（在庫/洗濯中/廃棄 等）")
B30: {=IFERROR(INDEX(貸出記録!$B:$B, SMALL(IF(貸出記録!$L:$L=1,ROW(貸出記録!$B:$B)),ROW(A11)) ),"")} | C30: =IF(B30="","", "貸出中なのに個体台帳の状態が一致しない（在庫/洗濯中/廃棄 等）")
B31: {=IFERROR(INDEX(貸出記録!$B:$B, SMALL(IF(貸出記録!$L:$L=1,ROW(貸出記録!$B:$B)),ROW(A12)) ),"")} | C31: =IF(B31="","", "貸出中なのに個体台帳の状態が一致しない（在庫/洗濯中/廃棄 等）")
B32: {=IFERROR(INDEX(貸出記録!$B:$B, SMALL(IF(貸出記録!$L:$L=1,ROW(貸出記録!$B:$B)),ROW(A13)) ),"")} | C32: =IF(B32="","", "貸出中なのに個体台帳の状態が一致しない（在庫/洗濯中/廃棄 等）")
... B39: {=IFERROR(INDEX(貸出記録!$B:$B, SMALL(IF(貸出記録!$L:$L=1,ROW(貸出記録!$B:$B)),ROW(A20)) ),"")} | C39: =IF(B39="","", "貸出中なのに個体台帳の状態が一致しない（在庫/洗濯中/廃棄 等）")
A40: 存在しないセット | B40: {=IFERROR(INDEX(貸出記録!B:B, SMALL( IF(ISNA(MATCH(貸出記録!B:B, セット台帳!A:A,0)), ROW(貸出記録!B:B)), ROW(A1) ) ),"")} -> 0
B41: {=IFERROR(INDEX(貸出記録!B:B, SMALL( IF(ISNA(MATCH(貸出記録!B:B, セット台帳!A:A,0)), ROW(貸出記録!B:B)), ROW(A2) ) ),"")} -> 0
B42: {=IFERROR(INDEX(貸出記録!B:B, SMALL( IF(ISNA(MATCH(貸出記録!B:B, セット台帳!A:A,0)), ROW(貸出記録!B:B)), ROW(A3) ) ),"")} -> 0
B43: {=IFERROR(INDEX(貸出記録!B:B, SMALL( IF(ISNA(MATCH(貸出記録!B:B, セット台帳!A:A,0)), ROW(貸出記録!B:B)), ROW(A4) ) ),"")} -> 0
B44: {=IFERROR(INDEX(貸出記録!B:B, SMALL( IF(ISNA(MATCH(貸出記録!B:B, セット台帳!A:A,0)), ROW(貸出記録!B:B)), ROW(A5) ) ),"")} -> 0
B45: {=IFERROR(INDEX(貸出記録!B:B, SMALL( IF(ISNA(MATCH(貸出記録!B:B, セット台帳!A:A,0)), ROW(貸出記録!B:B)), ROW(A6) ) ),"")} -> 0
B46: {=IFERROR(INDEX(貸出記録!B:B, SMALL( IF(ISNA(MATCH(貸出記録!B:B, セット台帳!A:A,0)), ROW(貸出記録!B:B)), ROW(A7) ) ),"")} -> 0
B47: {=IFERROR(INDEX(貸出記録!B:B, SMALL( IF(ISNA(MATCH(貸出記録!B:B, セット台帳!A:A,0)), ROW(貸出記録!B:B)), ROW(A8) ) ),"")} -> 0
B48: {=IFERROR(INDEX(貸出記録!B:B, SMALL( IF(ISNA(MATCH(貸出記録!B:B, セット台帳!A:A,0)), ROW(貸出記録!B:B)), ROW(A9) ) ),"")} -> 0
B49: {=IFERROR(INDEX(貸出記録!B:B, SMALL( IF(ISNA(MATCH(貸出記録!B:B, セット台帳!A:A,0)), ROW(貸出記録!B:B)), ROW(A10) ) ),"")} -> 0
B50: {=IFERROR(INDEX(貸出記録!B:B, SMALL( IF(ISNA(MATCH(貸出記録!B:B, セット台帳!A:A,0)), ROW(貸出記録!B:B)), ROW(A11) ) ),"")} -> 0
B51: {=IFERROR(INDEX(貸出記録!B:B, SMALL( IF(ISNA(MATCH(貸出記録!B:B, セット台帳!A:A,0)), ROW(貸出記録!B:B)), ROW(A12) ) ),"")} -> 0
...

Sheet 個体台帳
A1: セットID | B1: 個体ID | C1: 種類 | D1: カテゴリ | E1: 状態 | F1: 保管場所 | G1: 写真（ファイル名/パス） | H1: 備考 | I1: 写真ファイル名 | J1: 公開名 | K1: 公開/非公開
A2: SET-0001 | B2: ITM-0001 | C2: 服 | D2: メイド | E2: 在庫 | G2: =IF(OR($D2="",$I2=""),"",HYPERLINK(".\衣装写真\"&$D2&"\"&$I2,"写真")) -> 写真 | I2: ITM-0001.jpg | J2: ミントブルーのメイド服 | K2: 公開
A3: SET-0001 | B3: ITM-0002 | C3: 服 | D3: メイド | E3: 在庫 | G3: =IF(OR($D3="",$I3=""),"",HYPERLINK(".\衣装写真\"&$D3&"\"&$I3,"写真")) -> 写真 | I3: ITM-0002.jpg | J3: ミントブルーのメイド服 | K3: 公開
A4: SET-0001 | B4: ITM-0003 | C4: 服 | D4: メイド | E4: 在庫 | G4: =IF(OR($D4="",$I4=""),"",HYPERLINK(".\衣装写真\"&$D4&"\"&$I4,"写真")) -> 写真 | I4: ITM-0003.jpg | J4: ミントブルーのメイド服(エプロン付き) | K4: 公開
A5: SET-0001 | B5: ITM-0004 | C5: 服 | D5: メイド | E5: 在庫 | G5: =IF(OR($D5="",$I5=""),"",HYPERLINK(".\衣装写真\"&$D5&"\"&$I5,"写真")) -> 写真 | I5: ITM-0004.jpg | J5: ミントブルーのメイド服(装飾なし) | K5: 公開
A6: SET-0001 | B6: ITM-0005 | C6: 服 | D6: メイド | E6: 在庫 | G6: =IF(OR($D6="",$I6=""),"",HYPERLINK(".\衣装写真\"&$D6&"\"&$I6,"写真")) -> 写真 | I6: ITM-0005.jpg | J6: ミントブルーのメイド服 | K6: 公開
A7: SET-0001 | B7: ITM-0006 | C7: 服 | D7: メイド | E7: 在庫 | G7: =IF(OR($D7="",$I7=""),"",HYPERLINK(".\衣装写真\"&$D7&"\"&$I7,"写真")) -> 写真 | I7: ITM-0006.jpg | J7: ミントブルーのメイド服 | K7: 公開
A8: SET-0001 | B8: ITM-0007 | C8: 服 | D8: メイド | E8: 在庫 | G8: =IF(OR($D8="",$I8=""),"",HYPERLINK(".\衣装写真\"&$D8&"\"&$I8,"写真")) -> 写真 | I8: ITM-0007.jpg | J8: ラベンダー色のメイド服 | K8: 公開
A9: SET-0001 | B9: ITM-0008 | C9: 服 | D9: メイド | E9: 在庫 | G9: =IF(OR($D9="",$I9=""),"",HYPERLINK(".\衣装写真\"&$D9&"\"&$I9,"写真")) -> 写真 | I9: ITM-0008.jpg | J9: ラベンダー色のメイド服 | K9: 公開
A10: SET-0001 | B10: ITM-0009 | C10: 服 | D10: メイド | E10: 在庫 | G10: =IF(OR($D10="",$I10=""),"",HYPERLINK(".\衣装写真\"&$D10&"\"&$I10,"写真")) -> 写真 | I10: ITM-0009.jpg | J10: ミントブルーのメイド服 | K10: 公開
A11: SET-0001 | B11: ITM-0010 | C11: 服 | D11: メイド | E11: 在庫 | G11: =IF(OR($D11="",$I11=""),"",HYPERLINK(".\衣装写真\"&$D11&"\"&$I11,"写真")) -> 写真 | I11: ITM-0010.jpg | J11: ミントブルーのメイド服 | K11: 公開
A12: SET-0001 | B12: ITM-0011 | C12: 服 | D12: メイド | E12: 在庫 | G12: =IF(OR($D12="",$I12=""),"",HYPERLINK(".\衣装写真\"&$D12&"\"&$I12,"写真")) -> 写真 | I12: ITM-0011.jpg | J12: ラベンダー色のメイド服 | K12: 公開
A13: SET-0001 | B13: ITM-0012 | C13: 服 | D13: メイド | E13: 在庫 | G13: =IF(OR($D13="",$I13=""),"",HYPERLINK(".\衣装写真\"&$D13&"\"&$I13,"写真")) -> 写真 | I13: ITM-0012.jpg | J13: ラベンダー色のメイド服 | K13: 公開
B14: ITM-0013
B15: ITM-0014
B16: ITM-0015
B17: ITM-0016
B18: ITM-0017
B19: ITM-0018
B20: ITM-0019
B21: ITM-0020
B22: ITM-0021
B23: ITM-0022
B24: ITM-0023
B25: ITM-0024
... B500: ITM-0499

Sheet セット台帳
A1: セットID | B1: 服ID(関数表示) | C1: 小物1ID(関数表示） | D1: 小物2ID(関数表示) | E1: ジャンル(関数) | F1: 状態(関数) | G1: 保管場所 | H1: セット写真（ファイル名/パス） | I1: 備考
A2: SET-0001 | B2: {=IF(TRIM(A2)="","", _xlfn.TEXTJOIN(" , ",TRUE, IF((個体台帳!$A$2:$A$1000=TRIM(A2))*(個体台帳!$C$2:$C$1000="服"), 個体台帳!$B$2:$B$1000, "")))} -> ITM-0001 , ITM-0002 , ITM-0003 , ITM-0004 , ITM-0005 , ITM-0006 , ITM-0007 , ITM-0008 , ITM-0009 , ITM-0010 , ITM-0011 , ITM-0012 | C2: {=IF(TRIM(A2)="","", _xlfn.TEXTJOIN(" , ",TRUE, IF((個体台帳!$A$2:$A$1000=TRIM(A2))*(個体台帳!$C$2:$C$1000="小物1"), 個体台帳!$B$2:$B$1000, "")))} | D2: {=IF(TRIM(A2)="","", _xlfn.TEXTJOIN(" , ",TRUE, IF((個体台帳!$A$2:$A$1000=TRIM(A2))*(個体台帳!$C$2:$C$1000="小物2"), 個体台帳!$B$2:$B$1000, "")))} | E2: {=IF($A2="","", INDEX(個体台帳!$D$2:$D$1000, MATCH(1, (個体台帳!$A$2:$A$1000=$A2)* (個体台帳!$C$2:$C$1000="服"), 0)))} -> メイド | F2: {=IF($A2="","", IF(COUNTIFS(貸出記録!$B:$B,$A2,貸出記録!$E:$E,"")>0, "貸出中","在庫"))} -> 在庫
B3: {=IF(TRIM(A3)="","", _xlfn.TEXTJOIN(" , ",TRUE, IF((個体台帳!$A$2:$A$1000=TRIM(A3))*(個体台帳!$C$2:$C$1000="服"), 個体台帳!$B$2:$B$1000, "")))} | C3: {=IF(TRIM(A3)="","", _xlfn.TEXTJOIN(" , ",TRUE, IF((個体台帳!$A$2:$A$1000=TRIM(A3))*(個体台帳!$C$2:$C$1000="小物1"), 個体台帳!$B$2:$B$1000, "")))} | D3: {=IF(TRIM(A3)="","", _xlfn.TEXTJOIN(" , ",TRUE, IF((個体台帳!$A$2:$A$1000=TRIM(A3))*(個体台帳!$C$2:$C$1000="小物2"), 個体台帳!$B$2:$B$1000, "")))} | E3: {=IF($A3="","", INDEX(個体台帳!$D$2:$D$1000, MATCH(1, (個体台帳!$A$2:$A$1000=$A3)* (個体台帳!$C$2:$C$1000="服"), 0)))} | F3: {=IF($A3="","", IF(COUNTIFS(貸出記録!$B:$B,$A3,貸出記録!$E:$E,"")>0, "貸出中","在庫"))}
B4: {=IF(TRIM(A4)="","", _xlfn.TEXTJOIN(" , ",TRUE, IF((個体台帳!$A$2:$A$1000=TRIM(A4))*(個体台帳!$C$2:$C$1000="服"), 個体台帳!$B$2:$B$1000, "")))} | C4: {=IF(TRIM(A4)="","", _xlfn.TEXTJOIN(" , ",TRUE, IF((個体台帳!$A$2:$A$1000=TRIM(A4))*(個体台帳!$C$2:$C$1000="小物1"), 個体台帳!$B$2:$B$1000, "")))} | D4: {=IF(TRIM(A4)="","", _xlfn.TEXTJOIN(" , ",TRUE, IF((個体台帳!$A$2:$A$1000=TRIM(A4))*(個体台帳!$C$2:$C$1000="小物2"), 個体台帳!$B$2:$B$1000, "")))} | E4: {=IF($A4="","", INDEX(個体台帳!$D$2:$D$1000, MATCH(1, (個体台帳!$A$2:$A$1000=$A4)* (個体台帳!$C$2:$C$1000="服"), 0)))} | F4: {=IF($A4="","", IF(COUNTIFS(貸出記録!$B:$B,$A4,貸出記録!$E:$E,"")>0, "貸出中","在庫"))}
B5: {=IF(TRIM(A5)="","", _xlfn.TEXTJOIN(" , ",TRUE, IF((個体台帳!$A$2:$A$1000=TRIM(A5))*(個体台帳!$C$2:$C$1000="服"), 個体台帳!$B$2:$B$1000, "")))} | C5: {=IF(TRIM(A5)="","", _xlfn.TEXTJOIN(" , ",TRUE, IF((個体台帳!$A$2:$A$1000=TRIM(A5))*(個体台帳!$C$2:$C$1000="小物1"), 個体台帳!$B$2:$B$1000, "")))} | D5: {=IF(TRIM(A5)="","", _xlfn.TEXTJOIN(" , ",TRUE, IF((個体台帳!$A$2:$A$1000=TRIM(A5))*(個体台帳!$C$2:$C$1000="小物2"), 個体台帳!$B$2:$B$1000, "")))} | E5: {=IF($A5="","", INDEX(個体台帳!$D$2:$D$1000, MATCH(1, (個体台帳!$A$2:$A$1000=$A5)* (個体台帳!$C$2:$C$1000="服"), 0)))} | F5: {=IF($A5="","", IF(COUNTIFS(貸出記録!$B:$B,$A5,貸出記録!$E:$E,"")>0, "貸出中","在庫"))}
B6: {=IF(TRIM(A6)="","", _xlfn.TEXTJOIN(" , ",TRUE, IF((個体台帳!$A$2:$A$1000=TRIM(A6))*(個体台帳!$C$2:$C$1000="服"), 個体台帳!$B$2:$B$1000, "")))} | C6: {=IF(TRIM(A6)="","", _xlfn.TEXTJOIN(" , ",TRUE, IF((個体台帳!$A$2:$A$1000=TRIM(A6))*(個体台帳!$C$2:$C$1000="小物1"), 個体台帳!$B$2:$B$1000, "")))} | D6: {=IF(TRIM(A6)="","", _xlfn.TEXTJOIN(" , ",TRUE, IF((個体台帳!$A$2:$A$1000=TRIM(A6))*(個体台帳!$C$2:$C$1000="小物2"), 個体台帳!$B$2:$B$1000, "")))} | E6: {=IF($A6="","", INDEX(個体台帳!$D$2:$D$1000, MATCH(1, (個体台帳!$A$2:$A$1000=$A6)* (個体台帳!$C$2:$C$1000="服"), 0)))} | F6: {=IF($A6="","", IF(COUNTIFS(貸出記録!$B:$B,$A6,貸出記録!$E:$E,"")>0, "貸出中","在庫"))}
B7: {=IF(TRIM(A7)="","", _xlfn.TEXTJOIN(" , ",TRUE, IF((個体台帳!$A$2:$A$1000=TRIM(A7))*(個体台帳!$C$2:$C$1000="服"), 個体台帳!$B$2:$B$1000, "")))} | C7: {=IF(TRIM(A7)="","", _xlfn.TEXTJOIN(" , ",TRUE, IF((個体台帳!$A$2:$A$1000=TRIM(A7))*(個体台帳!$C$2:$C$1000="小物1"), 個体台帳!$B$2:$B$1000, "")))} | D7: {=IF(TRIM(A7)="","", _xlfn.TEXTJOIN(" , ",TRUE, IF((個体台帳!$A$2:$A$1000=TRIM(A7))*(個体台帳!$C$2:$C$1000="小物2"), 個体台帳!$B$2:$B$1000, "")))} | E7: {=IF($A7="","", INDEX(個体台帳!$D$2:$D$1000, MATCH(1, (個体台帳!$A$2:$A$1000=$A7)* (個体台帳!$C$2:$C$1000="服"), 0)))} | F7: {=IF($A7="","", IF(COUNTIFS(貸出記録!$B:$B,$A7,貸出記録!$E:$E,"")>0, "貸出中","在庫"))}
B8: {=IF(TRIM(A8)="","", _xlfn.TEXTJOIN(" , ",TRUE, IF((個体台帳!$A$2:$A$1000=TRIM(A8))*(個体台帳!$C$2:$C$1000="服"), 個体台帳!$B$2:$B$1000, "")))} | C8: {=IF(TRIM(A8)="","", _xlfn.TEXTJOIN(" , ",TRUE, IF((個体台帳!$A$2:$A$1000=TRIM(A8))*(個体台帳!$C$2:$C$1000="小物1"), 個体台帳!$B$2:$B$1000, "")))} | D8: {=IF(TRIM(A8)="","", _xlfn.TEXTJOIN(" , ",TRUE, IF((個体台帳!$A$2:$A$1000=TRIM(A8))*(個体台帳!$C$2:$C$1000="小物2"), 個体台帳!$B$2:$B$1000, "")))} | E8: {=IF($A8="","", INDEX(個体台帳!$D$2:$D$1000, MATCH(1, (個体台帳!$A$2:$A$1000=$A8)* (個体台帳!$C$2:$C$1000="服"), 0)))} | F8: {=IF($A8="","", IF(COUNTIFS(貸出記録!$B:$B,$A8,貸出記録!$E:$E,"")>0, "貸出中","在庫"))}
B9: {=IF(TRIM(A9)="","", _xlfn.TEXTJOIN(" , ",TRUE, IF((個体台帳!$A$2:$A$1000=TRIM(A9))*(個体台帳!$C$2:$C$1000="服"), 個体台帳!$B$2:$B$1000, "")))} | C9: {=IF(TRIM(A9)="","", _xlfn.TEXTJOIN(" , ",TRUE, IF((個体台帳!$A$2:$A$1000=TRIM(A9))*(個体台帳!$C$2:$C$1000="小物1"), 個体台帳!$B$2:$B$1000, "")))} | D9: {=IF(TRIM(A9)="","", _xlfn.TEXTJOIN(" , ",TRUE, IF((個体台帳!$A$2:$A$1000=TRIM(A9))*(個体台帳!$C$2:$C$1000="小物2"), 個体台帳!$B$2:$B$1000, "")))} | E9: {=IF($A9="","", INDEX(個体台帳!$D$2:$D$1000, MATCH(1, (個体台帳!$A$2:$A$1000=$A9)* (個体台帳!$C$2:$C$1000="服"), 0)))} | F9: {=IF($A9="","", IF(COUNTIFS(貸出記録!$B:$B,$A9,貸出記録!$E:$E,"")>0, "貸出中","在庫"))}
B10: {=IF(TRIM(A10)="","", _xlfn.TEXTJOIN(" , ",TRUE, IF((個体台帳!$A$2:$A$1000=TRIM(A10))*(個体台帳!$C$2:$C$1000="服"), 個体台帳!$B$2:$B$1000, "")))} | C10: {=IF(TRIM(A10)="","", _xlfn.TEXTJOIN(" , ",TRUE, IF((個体台帳!$A$2:$A$1000=TRIM(A10))*(個体台帳!$C$2:$C$1000="小物1"), 個体台帳!$B$2:$B$1000, "")))} | D10: {=IF(TRIM(A10)="","", _xlfn.TEXTJOIN(" , ",TRUE, IF((個体台帳!$A$2:$A$1000=TRIM(A10))*(個体台帳!$C$2:$C$1000="小物2"), 個体台帳!$B$2:$B$1000, "")))} | E10: {=IF($A10="","", INDEX(個体台帳!$D$2:$D$1000, MATCH(1, (個体台帳!$A$2:$A$1000=$A10)* (個体台帳!$C$2:$C$1000="服"), 0)))} | F10: {=IF($A10="","", IF(COUNTIFS(貸出記録!$B:$B,$A10,貸出記録!$E:$E,"")>0, "貸出中","在庫"))}
B11: {=IF(TRIM(A11)="","", _xlfn.TEXTJOIN(" , ",TRUE, IF((個体台帳!$A$2:$A$1000=TRIM(A11))*(個体台帳!$C$2:$C$1000="服"), 個体台帳!$B$2:$B$1000, "")))} | C11: {=IF(TRIM(A11)="","", _xlfn.TEXTJOIN(" , ",TRUE, IF((個体台帳!$A$2:$A$1000=TRIM(A11))*(個体台帳!$C$2:$C$1000="小物1"), 個体台帳!$B$2:$B$1000, "")))} | D11: {=IF(TRIM(A11)="","", _xlfn.TEXTJOIN(" , ",TRUE, IF((個体台帳!$A$2:$A$1000=TRIM(A11))*(個体台帳!$C$2:$C$1000="小物2"), 個体台帳!$B$2:$B$1000, "")))} | E11: {=IF($A11="","", INDEX(個体台帳!$D$2:$D$1000, MATCH(1, (個体台帳!$A$2:$A$1000=$A11)* (個体台帳!$C$2:$C$1000="服"), 0)))} | F11: {=IF($A11="","", IF(COUNTIFS(貸出記録!$B:$B,$A11,貸出記録!$E:$E,"")>0, "貸出中","在庫"))}
B12: {=IF(TRIM(A12)="","", _xlfn.TEXTJOIN(" , ",TRUE, IF((個体台帳!$A$2:$A$1000=TRIM(A12))*(個体台帳!$C$2:$C$1000="服"), 個体台帳!$B$2:$B$1000, "")))} | C12: {=IF(TRIM(A12)="","", _xlfn.TEXTJOIN(" , ",TRUE, IF((個体台帳!$A$2:$A$1000=TRIM(A12))*(個体台帳!$C$2:$C$1000="小物1"), 個体台帳!$B$2:$B$1000, "")))} | D12: {=IF(TRIM(A12)="","", _xlfn.TEXTJOIN(" , ",TRUE, IF((個体台帳!$A$2:$A$1000=TRIM(A12))*(個体台帳!$C$2:$C$1000="小物2"), 個体台帳!$B$2:$B$1000, "")))} | E12: {=IF($A12="","", INDEX(個体台帳!$D$2:$D$1000, MATCH(1, (個体台帳!$A$2:$A$1000=$A12)* (個体台帳!$C$2:$C$1000="服"), 0)))} | F12: {=IF($A12="","", IF(COUNTIFS(貸出記録!$B:$B,$A12,貸出記録!$E:$E,"")>0, "貸出中","在庫"))}
B13: {=IF(TRIM(A13)="","", _xlfn.TEXTJOIN(" , ",TRUE, IF((個体台帳!$A$2:$A$1000=TRIM(A13))*(個体台帳!$C$2:$C$1000="服"), 個体台帳!$B$2:$B$1000, "")))} | C13: {=IF(TRIM(A13)="","", _xlfn.TEXTJOIN(" , ",TRUE, IF((個体台帳!$A$2:$A$1000=TRIM(A13))*(個体台帳!$C$2:$C$1000="小物1"), 個体台帳!$B$2:$B$1000, "")))} | D13: {=IF(TRIM(A13)="","", _xlfn.TEXTJOIN(" , ",TRUE, IF((個体台帳!$A$2:$A$1000=TRIM(A13))*(個体台帳!$C$2:$C$1000="小物2"), 個体台帳!$B$2:$B$1000, "")))} | E13: {=IF($A13="","", INDEX(個体台帳!$D$2:$D$1000, MATCH(1, (個体台帳!$A$2:$A$1000=$A13)* (個体台帳!$C$2:$C$1000="服"), 0)))} | F13: {=IF($A13="","", IF(COUNTIFS(貸出記録!$B:$B,$A13,貸出記録!$E:$E,"")>0, "貸出中","在庫"))}
B14: {=IF(TRIM(A14)="","", _xlfn.TEXTJOIN(" , ",TRUE, IF((個体台帳!$A$2:$A$1000=TRIM(A14))*(個体台帳!$C$2:$C$1000="服"), 個体台帳!$B$2:$B$1000, "")))} | C14: {=IF(TRIM(A14)="","", _xlfn.TEXTJOIN(" , ",TRUE, IF((個体台帳!$A$2:$A$1000=TRIM(A14))*(個体台帳!$C$2:$C$1000="小物1"), 個体台帳!$B$2:$B$1000, "")))} | D14: {=IF(TRIM(A14)="","", _xlfn.TEXTJOIN(" , ",TRUE, IF((個体台帳!$A$2:$A$1000=TRIM(A14))*(個体台帳!$C$2:$C$1000="小物2"), 個体台帳!$B$2:$B$1000, "")))} | E14: {=IF($A14="","", INDEX(個体台帳!$D$2:$D$1000, MATCH(1, (個体台帳!$A$2:$A$1000=$A14)* (個体台帳!$C$2:$C$1000="服"), 0)))} | F14: {=IF($A14="","", IF(COUNTIFS(貸出記録!$B:$B,$A14,貸出記録!$E:$E,"")>0, "貸出中","在庫"))}
... B500: {=IF(TRIM(A500)="","", _xlfn.TEXTJOIN(" , ",TRUE, IF((個体台帳!$A$2:$A$1000=TRIM(A500))*(個体台帳!$C$2:$C$1000="服"), 個体台帳!$B$2:$B$1000, "")))} | C500: {=IF(TRIM(A500)="","", _xlfn.TEXTJOIN(" , ",TRUE, IF((個体台帳!$A$2:$A$1000=TRIM(A500))*(個体台帳!$C$2:$C$1000="小物1"), 個体台帳!$B$2:$B$1000, "")))} | D500: {=IF(TRIM(A500)="","", _xlfn.TEXTJOIN(" , ",TRUE, IF((個体台帳!$A$2:$A$1000=TRIM(A500))*(個体台帳!$C$2:$C$1000="小物2"), 個体台帳!$B$2:$B$1000, "")))} | E500: {=IF($A500="","", INDEX(個体台帳!$D$2:$D$1000, MATCH(1, (個体台帳!$A$2:$A$1000=$A500)* (個体台帳!$C$2:$C$1000="服"), 0)))} | F500: {=IF($A500="","", IF(COUNTIFS(貸出記録!$B:$B,$A500,貸出記録!$E:$E,"")>0, "貸出中","在庫"))}

Sheet 貸出記録
A1: 貸出ID | B1: セットID | C1: 貸出先 | D1: 貸出日 | E1: 返却日 | F1: 承認者 | G1: 状態メモ | H1: 備考 | I1: 補助列 | J1: 補助列2 | K1: 補助列3 | L1: 補助列4 | M1: 補助列5
A2: BT-0001 | I2: =IF($A2="","",--($E2="")) -> 1 | J2: =IF($D2="","",TODAY()-$D2) | K2: =IF($A2="","",IF(AND($E2="", $D2<>"", TODAY()-$D2>=31),1,0)) -> 0 | L2: =IF($A2="","",IF($E2<>"",0,IF(COUNTIFS(個体台帳!$A:$A,$B2,個体台帳!$E:$E,"<>貸出中")>0,1,0))) -> 0 | M2: =IF($A2="","",IF($E2<>"",0,IF(COUNTIFS(個体台帳!$A:$A,$B2,個体台帳!$E:$E,"廃棄")>0,1,0))) -> 0
A3: BT-0002 | I3: =IF($A3="","",--($E3="")) -> 1 | J3: =IF($D3="","",TODAY()-$D3) | K3: =IF($A3="","",IF(AND($E3="", $D3<>"", TODAY()-$D3>=31),1,0)) -> #VALUE! | L3: =IF($A3="","",IF($E3<>"",0,IF(COUNTIFS(個体台帳!$A:$A,$B3,個体台帳!$E:$E,"<>貸出中")>0,1,0))) -> 0 | M3: =IF($A3="","",IF($E3<>"",0,IF(COUNTIFS(個体台帳!$A:$A,$B3,個体台帳!$E:$E,"廃棄")>0,1,0))) -> 0
A4: BT-0003 | I4: =IF($A4="","",--($E4="")) -> 1 | J4: =IF($D4="","",TODAY()-$D4) | K4: =IF($A4="","",IF(AND($E4="", $D4<>"", TODAY()-$D4>=31),1,0)) -> #VALUE! | L4: =IF($A4="","",IF($E4<>"",0,IF(COUNTIFS(個体台帳!$A:$A,$B4,個体台帳!$E:$E,"<>貸出中")>0,1,0))) -> 1 | M4: =IF($A4="","",IF($E4<>"",0,IF(COUNTIFS(個体台帳!$A:$A,$B4,個体台帳!$E:$E,"廃棄")>0,1,0))) -> 0
A5: BT-0004 | I5: =IF($A5="","",--($E5="")) -> 1 | J5: =IF($D5="","",TODAY()-$D5) | K5: =IF($A5="","",IF(AND($E5="", $D5<>"", TODAY()-$D5>=31),1,0)) -> #VALUE! | L5: =IF($A5="","",IF($E5<>"",0,IF(COUNTIFS(個体台帳!$A:$A,$B5,個体台帳!$E:$E,"<>貸出中")>0,1,0))) -> 1 | M5: =IF($A5="","",IF($E5<>"",0,IF(COUNTIFS(個体台帳!$A:$A,$B5,個体台帳!$E:$E,"廃棄")>0,1,0))) -> 0
A6: BT-0005 | I6: =IF($A6="","",--($E6="")) -> 1 | J6: =IF($D6="","",TODAY()-$D6) | K6: =IF($A6="","",IF(AND($E6="", $D6<>"", TODAY()-$D6>=31),1,0)) -> #VALUE! | L6: =IF($A6="","",IF($E6<>"",0,IF(COUNTIFS(個体台帳!$A:$A,$B6,個体台帳!$E:$E,"<>貸出中")>0,1,0))) -> 1 | M6: =IF($A6="","",IF($E6<>"",0,IF(COUNTIFS(個体台帳!$A:$A,$B6,個体台帳!$E:$E,"廃棄")>0,1,0))) -> 0
A7: BT-0006 | I7: =IF($A7="","",--($E7="")) -> 1 | J7: =IF($D7="","",TODAY()-$D7) | K7: =IF($A7="","",IF(AND($E7="", $D7<>"", TODAY()-$D7>=31),1,0)) -> #VALUE! | L7: =IF($A7="","",IF($E7<>"",0,IF(COUNTIFS(個体台帳!$A:$A,$B7,個体台帳!$E:$E,"<>貸出中")>0,1,0))) -> 1 | M7: =IF($A7="","",IF($E7<>"",0,IF(COUNTIFS(個体台帳!$A:$A,$B7,個体台帳!$E:$E,"廃棄")>0,1,0))) -> 0
A8: BT-0007 | I8: =IF($A8="","",--($E8="")) -> 1 | J8: =IF($D8="","",TODAY()-$D8) | K8: =IF($A8="","",IF(AND($E8="", $D8<>"", TODAY()-$D8>=31),1,0)) -> #VALUE! | L8: =IF($A8="","",IF($E8<>"",0,IF(COUNTIFS(個体台帳!$A:$A,$B8,個体台帳!$E:$E,"<>貸出中")>0,1,0))) -> 1 | M8: =IF($A8="","",IF($E8<>"",0,IF(COUNTIFS(個体台帳!$A:$A,$B8,個体台帳!$E:$E,"廃棄")>0,1,0))) -> 0
A9: BT-0008 | I9: =IF($A9="","",--($E9="")) -> 1 | J9: =IF($D9="","",TODAY()-$D9) | K9: =IF($A9="","",IF(AND($E9="", $D9<>"", TODAY()-$D9>=31),1,0)) -> #VALUE! | L9: =IF($A9="","",IF($E9<>"",0,IF(COUNTIFS(個体台帳!$A:$A,$B9,個体台帳!$E:$E,"<>貸出中")>0,1,0))) -> 1 | M9: =IF($A9="","",IF($E9<>"",0,IF(COUNTIFS(個体台帳!$A:$A,$B9,個体台帳!$E:$E,"廃棄")>0,1,0))) -> 0
A10: BT-0009 | I10: =IF($A10="","",--($E10="")) -> 1 | J10: =IF($D10="","",TODAY()-$D10) | K10: =IF($A10="","",IF(AND($E10="", $D10<>"", TODAY()-$D10>=31),1,0)) -> #VALUE! | L10: =IF($A10="","",IF($E10<>"",0,IF(COUNTIFS(個体台帳!$A:$A,$B10,個体台帳!$E:$E,"<>貸出中")>0,1,0))) -> 1 | M10: =IF($A10="","",IF($E10<>"",0,IF(COUNTIFS(個体台帳!$A:$A,$B10,個体台帳!$E:$E,"廃棄")>0,1,0))) -> 0
A11: BT-0010 | I11: =IF($A11="","",--($E11="")) -> 1 | J11: =IF($D11="","",TODAY()-$D11) | K11: =IF($A11="","",IF(AND($E11="", $D11<>"", TODAY()-$D11>=31),1,0)) -> #VALUE! | L11: =IF($A11="","",IF($E11<>"",0,IF(COUNTIFS(個体台帳!$A:$A,$B11,個体台帳!$E:$E,"<>貸出中")>0,1,0))) -> 1 | M11: =IF($A11="","",IF($E11<>"",0,IF(COUNTIFS(個体台帳!$A:$A,$B11,個体台帳!$E:$E,"廃棄")>0,1,0))) -> 0
A12: BT-0011 | I12: =IF($A12="","",--($E12="")) -> 1 | J12: =IF($D12="","",TODAY()-$D12) | K12: =IF($A12="","",IF(AND($E12="", $D12<>"", TODAY()-$D12>=31),1,0)) -> #VALUE! | L12: =IF($A12="","",IF($E12<>"",0,IF(COUNTIFS(個体台帳!$A:$A,$B12,個体台帳!$E:$E,"<>貸出中")>0,1,0))) -> 1 | M12: =IF($A12="","",IF($E12<>"",0,IF(COUNTIFS(個体台帳!$A:$A,$B12,個体台帳!$E:$E,"廃棄")>0,1,0))) -> 0
A13: BT-0012 | I13: =IF($A13="","",--($E13="")) -> 1 | J13: =IF($D13="","",TODAY()-$D13) | K13: =IF($A13="","",IF(AND($E13="", $D13<>"", TODAY()-$D13>=31),1,0)) -> #VALUE! | L13: =IF($A13="","",IF($E13<>"",0,IF(COUNTIFS(個体台帳!$A:$A,$B13,個体台帳!$E:$E,"<>貸出中")>0,1,0))) -> 1 | M13: =IF($A13="","",IF($E13<>"",0,IF(COUNTIFS(個体台帳!$A:$A,$B13,個体台帳!$E:$E,"廃棄")>0,1,0))) -> 0
... A500: BT-0499 | I500: =IF($A500="","",--($E500="")) -> 1 | J500: =IF($D500="","",TODAY()-$D500) | K500: =IF($A500="","",IF(AND($E500="", $D500<>"", TODAY()-$D500>=31),1,0)) -> #VALUE! | L500: =IF($A500="","",IF($E500<>"",0,IF(COUNTIFS(個体台帳!$A:$A,$B500,個体台帳!$E:$E,"<>貸出中")>0,1,0))) -> 1 | M500: =IF($A500="","",IF($E500<>"",0,IF(COUNTIFS(個体台帳!$A:$A,$B500,個体台帳!$E:$E,"廃棄")>0,1,0))) -> 0

Sheet 現在貸出中
A1: 貸出ID | B1: セットID | C1: 貸出先 | D1: 貸出日 | E1: 経過日数 | F1: 承認者
A2: {=IFERROR( INDEX(貸出記録!$A$2:$A$5000, SMALL( IF(貸出記録!$E$2:$E$5000="", ROW(貸出記録!$A$2:$A$5000)-ROW(貸出記録!$A$2)+1), ROW(A1) ) ), "")} -> BT-0001 | B2: {=IF($A2="","", IFERROR(IF(INDEX(貸出記録!$B$2:$B$5000, MATCH($A2,貸出記録!$A$2:$A$5000,0))="","", INDEX(貸出記録!$B$2:$B$5000, MATCH($A2,貸出記録!$A$2:$A$5000,0)) ),""))} | C2: {=IF($A2="","", IFERROR(IF(INDEX(貸出記録!$C$2:$C$5000, MATCH($A2,貸出記録!$A$2:$A$5000,0))="","", INDEX(貸出記録!$C$2:$C$5000, MATCH($A2,貸出記録!$A$2:$A$5000,0)) ),""))} | D2: {=IF($A2="","", IFERROR(IF(INDEX(貸出記録!$D:$D, MATCH($A2,貸出記録!$A:$A,0))="","", INDEX(貸出記録!$D:$D, MATCH($A2,貸出記録!$A:$A,0)) ),""))} | E2: {=IF(D2="","",TODAY()-D2&"日")} | F2: {=IF($A2="","", IFERROR(IF(INDEX(貸出記録!$F:$F, MATCH($A2,貸出記録!$A:$A,0))="","", INDEX(貸出記録!$F:$F, MATCH($A2,貸出記録!$A:$A,0)) ),""))}
A3: {=IFERROR( INDEX(貸出記録!$A$2:$A$5000, SMALL( IF(貸出記録!$E$2:$E$5000="", ROW(貸出記録!$A$2:$A$5000)-ROW(貸出記録!$A$2)+1), ROW(A2) ) ), "")} -> BT-0002 | B3: {=IF($A3="","", IFERROR(IF(INDEX(貸出記録!$B$2:$B$5000, MATCH($A3,貸出記録!$A$2:$A$5000,0))="","", INDEX(貸出記録!$B$2:$B$5000, MATCH($A3,貸出記録!$A$2:$A$5000,0)) ),""))} | C3: {=IF($A3="","", IFERROR(IF(INDEX(貸出記録!$C$2:$C$5000, MATCH($A3,貸出記録!$A$2:$A$5000,0))="","", INDEX(貸出記録!$C$2:$C$5000, MATCH($A3,貸出記録!$A$2:$A$5000,0)) ),""))} | D3: {=IF($A3="","", IFERROR(IF(INDEX(貸出記録!$D:$D, MATCH($A3,貸出記録!$A:$A,0))="","", INDEX(貸出記録!$D:$D, MATCH($A3,貸出記録!$A:$A,0)) ),""))} | E3: {=IF(D3="","",TODAY()-D3&"日")} | F3: {=IF($A3="","", IFERROR(IF(INDEX(貸出記録!$F:$F, MATCH($A3,貸出記録!$A:$A,0))="","", INDEX(貸出記録!$F:$F, MATCH($A3,貸出記録!$A:$A,0)) ),""))}
A4: {=IFERROR( INDEX(貸出記録!$A$2:$A$5000, SMALL( IF(貸出記録!$E$2:$E$5000="", ROW(貸出記録!$A$2:$A$5000)-ROW(貸出記録!$A$2)+1), ROW(A3) ) ), "")} -> BT-0003 | B4: {=IF($A4="","", IFERROR(IF(INDEX(貸出記録!$B$2:$B$5000, MATCH($A4,貸出記録!$A$2:$A$5000,0))="","", INDEX(貸出記録!$B$2:$B$5000, MATCH($A4,貸出記録!$A$2:$A$5000,0)) ),""))} | C4: {=IF($A4="","", IFERROR(IF(INDEX(貸出記録!$C$2:$C$5000, MATCH($A4,貸出記録!$A$2:$A$5000,0))="","", INDEX(貸出記録!$C$2:$C$5000, MATCH($A4,貸出記録!$A$2:$A$5000,0)) ),""))} | D4: {=IF($A4="","", IFERROR(IF(INDEX(貸出記録!$D:$D, MATCH($A4,貸出記録!$A:$A,0))="","", INDEX(貸出記録!$D:$D, MATCH($A4,貸出記録!$A:$A,0)) ),""))} | E4: {=IF(D4="","",TODAY()-D4&"日")} | F4: {=IF($A4="","", IFERROR(IF(INDEX(貸出記録!$F:$F, MATCH($A4,貸出記録!$A:$A,0))="","", INDEX(貸出記録!$F:$F, MATCH($A4,貸出記録!$A:$A,0)) ),""))}
A5: {=IFERROR( INDEX(貸出記録!$A$2:$A$5000, SMALL( IF(貸出記録!$E$2:$E$5000="", ROW(貸出記録!$A$2:$A$5000)-ROW(貸出記録!$A$2)+1), ROW(A4) ) ), "")} -> BT-0004 | B5: {=IF($A5="","", IFERROR(IF(INDEX(貸出記録!$B$2:$B$5000, MATCH($A5,貸出記録!$A$2:$A$5000,0))="","", INDEX(貸出記録!$B$2:$B$5000, MATCH($A5,貸出記録!$A$2:$A$5000,0)) ),""))} | C5: {=IF($A5="","", IFERROR(IF(INDEX(貸出記録!$C$2:$C$5000, MATCH($A5,貸出記録!$A$2:$A$5000,0))="","", INDEX(貸出記録!$C$2:$C$5000, MATCH($A5,貸出記録!$A$2:$A$5000,0)) ),""))} | D5: {=IF($A5="","", IFERROR(IF(INDEX(貸出記録!$D:$D, MATCH($A5,貸出記録!$A:$A,0))="","", INDEX(貸出記録!$D:$D, MATCH($A5,貸出記録!$A:$A,0)) ),""))} | E5: {=IF(D5="","",TODAY()-D5&"日")} | F5: {=IF($A5="","", IFERROR(IF(INDEX(貸出記録!$F:$F, MATCH($A5,貸出記録!$A:$A,0))="","", INDEX(貸出記録!$F:$F, MATCH($A5,貸出記録!$A:$A,0)) ),""))}
A6: {=IFERROR( INDEX(貸出記録!$A$2:$A$5000, SMALL( IF(貸出記録!$E$2:$E$5000="", ROW(貸出記録!$A$2:$A$5000)-ROW(貸出記録!$A$2)+1), ROW(A5) ) ), "")} -> BT-0005 | B6: {=IF($A6="","", IFERROR(IF(INDEX(貸出記録!$B$2:$B$5000, MATCH($A6,貸出記録!$A$2:$A$5000,0))="","", INDEX(貸出記録!$B$2:$B$5000, MATCH($A6,貸出記録!$A$2:$A$5000,0)) ),""))} | C6: {=IF($A6="","", IFERROR(IF(INDEX(貸出記録!$C$2:$C$5000, MATCH($A6,貸出記録!$A$2:$A$5000,0))="","", INDEX(貸出記録!$C$2:$C$5000, MATCH($A6,貸出記録!$A$2:$A$5000,0)) ),""))} | D6: {=IF($A6="","", IFERROR(IF(INDEX(貸出記録!$D:$D, MATCH($A6,貸出記録!$A:$A,0))="","", INDEX(貸出記録!$D:$D, MATCH($A6,貸出記録!$A:$A,0)) ),""))} | E6: {=IF(D6="","",TODAY()-D6&"日")} | F6: {=IF($A6="","", IFERROR(IF(INDEX(貸出記録!$F:$F, MATCH($A6,貸出記録!$A:$A,0))="","", INDEX(貸出記録!$F:$F, MATCH($A6,貸出記録!$A:$A,0)) ),""))}
A7: {=IFERROR( INDEX(貸出記録!$A$2:$A$5000, SMALL( IF(貸出記録!$E$2:$E$5000="", ROW(貸出記録!$A$2:$A$5000)-ROW(貸出記録!$A$2)+1), ROW(A6) ) ), "")} -> BT-0006 | B7: {=IF($A7="","", IFERROR(IF(INDEX(貸出記録!$B$2:$B$5000, MATCH($A7,貸出記録!$A$2:$A$5000,0))="","", INDEX(貸出記録!$B$2:$B$5000, MATCH($A7,貸出記録!$A$2:$A$5000,0)) ),""))} | C7: {=IF($A7="","", IFERROR(IF(INDEX(貸出記録!$C$2:$C$5000, MATCH($A7,貸出記録!$A$2:$A$5000,0))="","", INDEX(貸出記録!$C$2:$C$5000, MATCH($A7,貸出記録!$A$2:$A$5000,0)) ),""))} | D7: {=IF($A7="","", IFERROR(IF(INDEX(貸出記録!$D:$D, MATCH($A7,貸出記録!$A:$A,0))="","", INDEX(貸出記録!$D:$D, MATCH($A7,貸出記録!$A:$A,0)) ),""))} | E7: {=IF(D7="","",TODAY()-D7&"日")} | F7: {=IF($A7="","", IFERROR(IF(INDEX(貸出記録!$F:$F, MATCH($A7,貸出記録!$A:$A,0))="","", INDEX(貸出記録!$F:$F, MATCH($A7,貸出記録!$A:$A,0)) ),""))}
A8: {=IFERROR( INDEX(貸出記録!$A$2:$A$5000, SMALL( IF(貸出記録!$E$2:$E$5000="", ROW(貸出記録!$A$2:$A$5000)-ROW(貸出記録!$A$2)+1), ROW(A7) ) ), "")} -> BT-0007 | B8: {=IF($A8="","", IFERROR(IF(INDEX(貸出記録!$B$2:$B$5000, MATCH($A8,貸出記録!$A$2:$A$5000,0))="","", INDEX(貸出記録!$B$2:$B$5000, MATCH($A8,貸出記録!$A$2:$A$5000,0)) ),""))} | C8: {=IF($A8="","", IFERROR(IF(INDEX(貸出記録!$C$2:$C$5000, MATCH($A8,貸出記録!$A$2:$A$5000,0))="","", INDEX(貸出記録!$C$2:$C$5000, MATCH($A8,貸出記録!$A$2:$A$5000,0)) ),""))} | D8: {=IF($A8="","", IFERROR(IF(INDEX(貸出記録!$D:$D, MATCH($A8,貸出記録!$A:$A,0))="","", INDEX(貸出記録!$D:$D, MATCH($A8,貸出記録!$A:$A,0)) ),""))} | E8: {=IF(D8="","",TODAY()-D8&"日")} | F8: {=IF($A8="","", IFERROR(IF(INDEX(貸出記録!$F:$F, MATCH($A8,貸出記録!$A:$A,0))="","", INDEX(貸出記録!$F:$F, MATCH($A8,貸出記録!$A:$A,0)) ),""))}
A9: {=IFERROR( INDEX(貸出記録!$A$2:$A$5000, SMALL( IF(貸出記録!$E$2:$E$5000="", ROW(貸出記録!$A$2:$A$5000)-ROW(貸出記録!$A$2)+1), ROW(A8) ) ), "")} -> BT-0008 | B9: {=IF($A9="","", IFERROR(IF(INDEX(貸出記録!$B$2:$B$5000, MATCH($A9,貸出記録!$A$2:$A$5000,0))="","", INDEX(貸出記録!$B$2:$B$5000, MATCH($A9,貸出記録!$A$2:$A$5000,0)) ),""))} | C9: {=IF($A9="","", IFERROR(IF(INDEX(貸出記録!$C$2:$C$5000, MATCH($A9,貸出記録!$A$2:$A$5000,0))="","", INDEX(貸出記録!$C$2:$C$5000, MATCH($A9,貸出記録!$A$2:$A$5000,0)) ),""))} | D9: {=IF($A9="","", IFERROR(IF(INDEX(貸出記録!$D:$D, MATCH($A9,貸出記録!$A:$A,0))="","", INDEX(貸出記録!$D:$D, MATCH($A9,貸出記録!$A:$A,0)) ),""))} | E9: {=IF(D9="","",TODAY()-D9&"日")} | F9: {=IF($A9="","", IFERROR(IF(INDEX(貸出記録!$F:$F, MATCH($A9,貸出記録!$A:$A,0))="","", INDEX(貸出記録!$F:$F, MATCH($A9,貸出記録!$A:$A,0)) ),""))}
A10: {=IFERROR( INDEX(貸出記録!$A$2:$A$5000, SMALL( IF(貸出記録!$E$2:$E$5000="", ROW(貸出記録!$A$2:$A$5000)-ROW(貸出記録!$A$2)+1), ROW(A9) ) ), "")} -> BT-0009 | B10: {=IF($A10="","", IFERROR(IF(INDEX(貸出記録!$B$2:$B$5000, MATCH($A10,貸出記録!$A$2:$A$5000,0))="","", INDEX(貸出記録!$B$2:$B$5000, MATCH($A10,貸出記録!$A$2:$A$5000,0)) ),""))} | C10: {=IF($A10="","", IFERROR(IF(INDEX(貸出記録!$C$2:$C$5000, MATCH($A10,貸出記録!$A$2:$A$5000,0))="","", INDEX(貸出記録!$C$2:$C$5000, MATCH($A10,貸出記録!$A$2:$A$5000,0)) ),""))} | D10: {=IF($A10="","", IFERROR(IF(INDEX(貸出記録!$D:$D, MATCH($A10,貸出記録!$A:$A,0))="","", INDEX(貸出記録!$D:$D, MATCH($A10,貸出記録!$A:$A,0)) ),""))} | E10: {=IF(D10="","",TODAY()-D10&"日")} | F10: {=IF($A10="","", IFERROR(IF(INDEX(貸出記録!$F:$F, MATCH($A10,貸出記録!$A:$A,0))="","", INDEX(貸出記録!$F:$F, MATCH($A10,貸出記録!$A:$A,0)) ),""))}
A11: {=IFERROR( INDEX(貸出記録!$A$2:$A$5000, SMALL( IF(貸出記録!$E$2:$E$5000="", ROW(貸出記録!$A$2:$A$5000)-ROW(貸出記録!$A$2)+1), ROW(A10) ) ), "")} -> BT-0010 | B11: {=IF($A11="","", IFERROR(IF(INDEX(貸出記録!$B$2:$B$5000, MATCH($A11,貸出記録!$A$2:$A$5000,0))="","", INDEX(貸出記録!$B$2:$B$5000, MATCH($A11,貸出記録!$A$2:$A$5000,0)) ),""))} | C11: {=IF($A11="","", IFERROR(IF(INDEX(貸出記録!$C$2:$C$5000, MATCH($A11,貸出記録!$A$2:$A$5000,0))="","", INDEX(貸出記録!$C$2:$C$5000, MATCH($A11,貸出記録!$A$2:$A$5000,0)) ),""))} | D11: {=IF($A11="","", IFERROR(IF(INDEX(貸出記録!$D:$D, MATCH($A11,貸出記録!$A:$A,0))="","", INDEX(貸出記録!$D:$D, MATCH($A11,貸出記録!$A:$A,0)) ),""))} | E11: {=IF(D11="","",TODAY()-D11&"日")} | F11: {=IF($A11="","", IFERROR(IF(INDEX(貸出記録!$F:$F, MATCH($A11,貸出記録!$A:$A,0))="","", INDEX(貸出記録!$F:$F, MATCH($A11,貸出記録!$A:$A,0)) ),""))}
A12: {=IFERROR( INDEX(貸出記録!$A$2:$A$5000, SMALL( IF(貸出記録!$E$2:$E$5000="", ROW(貸出記録!$A$2:$A$5000)-ROW(貸出記録!$A$2)+1), ROW(A11) ) ), "")} -> BT-0011 | B12: {=IF($A12="","", IFERROR(IF(INDEX(貸出記録!$B$2:$B$5000, MATCH($A12,貸出記録!$A$2:$A$5000,0))="","", INDEX(貸出記録!$B$2:$B$5000, MATCH($A12,貸出記録!$A$2:$A$5000,0)) ),""))} | C12: {=IF($A12="","", IFERROR(IF(INDEX(貸出記録!$C$2:$C$5000, MATCH($A12,貸出記録!$A$2:$A$5000,0))="","", INDEX(貸出記録!$C$2:$C$5000, MATCH($A12,貸出記録!$A$2:$A$5000,0)) ),""))} | D12: {=IF($A12="","", IFERROR(IF(INDEX(貸出記録!$D:$D, MATCH($A12,貸出記録!$A:$A,0))="","", INDEX(貸出記録!$D:$D, MATCH($A12,貸出記録!$A:$A,0)) ),""))} | E12: {=IF(D12="","",TODAY()-D12&"日")} | F12: {=IF($A12="","", IFERROR(IF(INDEX(貸出記録!$F:$F, MATCH($A12,貸出記録!$A:$A,0))="","", INDEX(貸出記録!$F:$F, MATCH($A12,貸出記録!$A:$A,0)) ),""))}
A13: {=IFERROR( INDEX(貸出記録!$A$2:$A$5000, SMALL( IF(貸出記録!$E$2:$E$5000="", ROW(貸出記録!$A$2:$A$5000)-ROW(貸出記録!$A$2)+1), ROW(A12) ) ), "")} -> BT-0012 | B13: {=IF($A13="","", IFERROR(IF(INDEX(貸出記録!$B$2:$B$5000, MATCH($A13,貸出記録!$A$2:$A$5000,0))="","", INDEX(貸出記録!$B$2:$B$5000, MATCH($A13,貸出記録!$A$2:$A$5000,0)) ),""))} | C13: {=IF($A13="","", IFERROR(IF(INDEX(貸出記録!$C$2:$C$5000, MATCH($A13,貸出記録!$A$2:$A$5000,0))="","", INDEX(貸出記録!$C$2:$C$5000, MATCH($A13,貸出記録!$A$2:$A$5000,0)) ),""))} | D13: {=IF($A13="","", IFERROR(IF(INDEX(貸出記録!$D:$D, MATCH($A13,貸出記録!$A:$A,0))="","", INDEX(貸出記録!$D:$D, MATCH($A13,貸出記録!$A:$A,0)) ),""))} | E13: {=IF(D13="","",TODAY()-D13&"日")} | F13: {=IF($A13="","", IFERROR(IF(INDEX(貸出記録!$F:$F, MATCH($A13,貸出記録!$A:$A,0))="","", INDEX(貸出記録!$F:$F, MATCH($A13,貸出記録!$A:$A,0)) ),""))}
... A300: {=IFERROR( INDEX(貸出記録!$A$2:$A$5000, SMALL( IF(貸出記録!$E$2:$E$5000="", ROW(貸出記録!$A$2:$A$5000)-ROW(貸出記録!$A$2)+1), ROW(A299) ) ), "")} -> BT-0299 | B300: {=IF($A300="","", IFERROR(IF(INDEX(貸出記録!$B$2:$B$5000, MATCH($A300,貸出記録!$A$2:$A$5000,0))="","", INDEX(貸出記録!$B$2:$B$5000, MATCH($A300,貸出記録!$A$2:$A$5000,0)) ),""))} | C300: {=IF($A300="","", IFERROR(IF(INDEX(貸出記録!$C$2:$C$5000, MATCH($A300,貸出記録!$A$2:$A$5000,0))="","", INDEX(貸出記録!$C$2:$C$5000, MATCH($A300,貸出記録!$A$2:$A$5000,0)) ),""))} | D300: {=IF($A300="","", IFERROR(IF(INDEX(貸出記録!$D:$D, MATCH($A300,貸出記録!$A:$A,0))="","", INDEX(貸出記録!$D:$D, MATCH($A300,貸出記録!$A:$A,0)) ),""))} | E300: {=IF(D300="","",TODAY()-D300&"日")} | F300: {=IF($A300="","", IFERROR(IF(INDEX(貸出記録!$F:$F, MATCH($A300,貸出記録!$A:$A,0))="","", INDEX(貸出記録!$F:$F, MATCH($A300,貸出記録!$A:$A,0)) ),""))}
